/home/users/mendrika/virtual-env/DeepLearning/bin/python: can't open file '/home/users/mendrika/Zambia-Intercomparison/ ': [Errno 2] No such file or directory
E1010 13:36:50.692000 3611719 torch/distributed/elastic/multiprocessing/api.py:874] failed (exitcode: 2) local_rank: 0 (pid: 3611746) of binary: /home/users/mendrika/virtual-env/DeepLearning/bin/python
Traceback (most recent call last):
  File "/home/users/mendrika/virtual-env/DeepLearning/bin/torchrun", line 8, in <module>
    sys.exit(main())
             ^^^^^^
  File "/home/users/mendrika/virtual-env/DeepLearning/lib/python3.12/site-packages/torch/distributed/elastic/multiprocessing/errors/__init__.py", line 355, in wrapper
    return f(*args, **kwargs)
           ^^^^^^^^^^^^^^^^^^
  File "/home/users/mendrika/virtual-env/DeepLearning/lib/python3.12/site-packages/torch/distributed/run.py", line 892, in main
    run(args)
  File "/home/users/mendrika/virtual-env/DeepLearning/lib/python3.12/site-packages/torch/distributed/run.py", line 883, in run
    elastic_launch(
  File "/home/users/mendrika/virtual-env/DeepLearning/lib/python3.12/site-packages/torch/distributed/launcher/api.py", line 139, in __call__
    return launch_agent(self._config, self._entrypoint, list(args))
           ^^^^^^^^^^^^^^^^^^^^^^^^^^^^^^^^^^^^^^^^^^^^^^^^^^^^^^^^
  File "/home/users/mendrika/virtual-env/DeepLearning/lib/python3.12/site-packages/torch/distributed/launcher/api.py", line 270, in launch_agent
    raise ChildFailedError(
torch.distributed.elastic.multiprocessing.errors.ChildFailedError: 
============================================================
  FAILED
------------------------------------------------------------
Failures:
  <NO_OTHER_FAILURES>
------------------------------------------------------------
Root Cause (first observed failure):
[0]:
  time      : 2025-10-10_13:36:50
  host      : gpuhost016.jc.rl.ac.uk
  rank      : 0 (local_rank: 0)
  exitcode  : 2 (pid: 3611746)
  error_file: <N/A>
  traceback : To enable traceback see: https://pytorch.org/docs/stable/elastic/errors.html
============================================================
/var/spool/slurmd/job45279381/slurm_script: line 43: --nproc_per_node=4: command not found
import: unable to open X server `' @ error/import.c/ImportImageCommand/346.
import: unable to open X server `' @ error/import.c/ImportImageCommand/346.
import: unable to open X server `' @ error/import.c/ImportImageCommand/346.
import: unable to open X server `' @ error/import.c/ImportImageCommand/346.
/home/users/mendrika/Zambia-Intercomparison/models/training/zambia-train.py: line 5: from: command not found
import: unable to open X server `' @ error/import.c/ImportImageCommand/346.
/home/users/mendrika/Zambia-Intercomparison/models/training/zambia-train.py: line 7: from: command not found
/home/users/mendrika/Zambia-Intercomparison/models/training/zambia-train.py: line 8: from: command not found
/home/users/mendrika/Zambia-Intercomparison/models/training/zambia-train.py: line 9: from: command not found
/home/users/mendrika/Zambia-Intercomparison/models/training/zambia-train.py: line 14: LEAD_TIME: command not found
/home/users/mendrika/Zambia-Intercomparison/models/training/zambia-train.py: line 15: BASE_DIR: command not found
/home/users/mendrika/Zambia-Intercomparison/models/training/zambia-train.py: line 16: TRAIN_DIR: command not found
/home/users/mendrika/Zambia-Intercomparison/models/training/zambia-train.py: line 17: VAL_DIR: command not found
/home/users/mendrika/Zambia-Intercomparison/models/training/zambia-train.py: line 18: BATCH_SIZE: command not found
/home/users/mendrika/Zambia-Intercomparison/models/training/zambia-train.py: line 20: CHECKPOINT_DIR: command not found
/home/users/mendrika/Zambia-Intercomparison/models/training/zambia-train.py: line 21: syntax error near unexpected token `CHECKPOINT_DIR,'
/home/users/mendrika/Zambia-Intercomparison/models/training/zambia-train.py: line 21: `os.makedirs(CHECKPOINT_DIR, exist_ok=True)'
